<mujoco>
<compiler angle="degree"
        inertiafromgeom="true"
        texturedir="textures/"
        meshdir="mesh/visual/"
        
        />
<option timestep="2e-3"
        iterations="100"
        tolerance="1e-10"
        impratio="10"/>


<default>
    <!-- <site rgba="0.8 0.6 0.7 0.3" type="ellipsoid" group="3"/> -->
    <!-- <geom contype='1' conaffinity='1' condim='4'  margin="1e-3" solref=".01 1" solimp=".99 .99 .01" /> -->
    <joint armature="0.01" damping=".1"/>
    <default class="UR5">
        <joint damping='.1'/>
    </default>
    <default class="UR5e">
        <joint damping='.1'/>
    </default>
    <default class="GRIPPER">
        <joint damping='.1'/>
    </default>
</default>

<visual>
    <map fogstart="3" fogend="5" znear="0.05"/>
    <quality shadowsize="2048"/>
    <scale framelength="0.1"
           framewidth="0.005"
           contactwidth="0.1"
           contactheight="0.005"
           forcewidth="0.01"/>
</visual>


<asset>
        <!--Meshes-->
        <mesh name="base"           file="base.stl"     />
        <mesh name="shoulder"       file="shoulder.stl" />
        <mesh name="upperarm"       file="upperarm.stl" />
        <mesh name="forearm"        file="forearm.stl"  />
        <mesh name="wrist1"         file="wrist1.stl"   />
        <mesh name="wrist2"         file="wrist2.stl"   />
        <mesh name="wrist3"         file="wrist3.stl"   />
        <mesh name="gripperpalm"    file="palm.STL"     />
        <mesh name="link_0"         file="link_0.STL"   />
        <mesh name="link_1"         file="link_1.STL"   />
        <mesh name="link_2"         file="link_2.STL"   />
        <mesh name="link_3"         file="link_3.STL"   />
        <mesh name="servo_motor"    file="servo_motor.stl"   scale="0.002 0.0025 0.002"  />
        <mesh name="bracket"        file="bracket.STL"       scale="0.002 0.002 0.002"  />

        <mesh name="robotiq_85_base_link_coarse" file="robotiq_85_base_link_coarse.STL" />
        <mesh name="inner_knuckle_coarse" file="inner_knuckle_coarse.STL" />
        <mesh name="inner_finger_coarse" file="inner_finger_coarse.STL" />
        <mesh name="outer_knuckle_coarse" file="outer_knuckle_coarse.STL" />
        <mesh name="outer_finger_coarse" file="outer_finger_coarse.STL" />

        <!--Textures-->
        <texture name="ur5_tex"     type="2d"       builtin="flat" height="32" width="32" rgb1="0.45 0.45 0.45" />
        <texture name="gripper_tex" type="2d"       builtin="flat" height="32" width="32" rgb1="0.45 0.45 0.45" rgb2="0 0 0"/>
        <texture name="bench_tex"   type="2d"       builtin="flat" height="32" width="32" rgb1="0.7 0.7 0.7" />
        <texture name="sky_tex"     type="skybox"   builtin="gradient" width="100" height="100" rgb1="1 1 1" rgb2="0.3 0.3 0.8" />
        <texture name="texgeom"     type="cube"     builtin="flat" mark="cross" width="127" height="1278" rgb1="0.8 0.6 0.4" rgb2="0.8 0.6 0.4" markrgb="1 1 1" random="0.01" />
        <texture name="floor_tex"   type="2d"        builtin="checker" rgb1=".2 .3 .4" rgb2=".1 .2 .3" width="100" height="100" />
        <texture name="wood"        type="cube"     file="wood2.png"/>
        <texture name="metal"        type="cube"     file="metal2.png"/>
        <texture name="plastic"     type="2d"       builtin="flat" height="32" width="32" />


        <!--Materials-->
        <material name="ur5_mat"        texture="ur5_tex"   shininess="0.9" specular="0.75" reflectance="0.3"/>
        <material name="gripper_mat"    texture="gripper_tex"   shininess="0.9" specular="0.75" reflectance="0.4"/>
        <material name='floor_mat'      texture="floor_tex"  shininess="0.8" texrepeat="10 10" specular="0.7"  reflectance="0.5" />
        <material name='geom'           texture="texgeom"   texuniform="true" />
        <material name="bench_mat"      texture="metal"   shininess="0.1" specular="0.5" reflectance="0.2"/>
        <material name="tablecube"      texture="wood" rgba=".8 .8 .8 1"/>
        <material name="hard_plastic"    texture="plastic" />
    </asset>

  <worldbody>
    <light name="lamp" active="true" directional="true" cutoff="4" exponent="20" diffuse="1 1 1" specular="0 0 0" pos="0 0 2.5" dir="0 0 -1 "/>
    <!-- <light diffuse=".5 .5 .5" pos="0.1 0.1 0.1" dir="0 0 -1"/> -->
    <geom type="plane" size="50 50 0.1" rgba=".9 .9 .9 1"/>

    <body name="carbase" pos="0 0 1 " euler="0 90 0">
      <joint type="free"/>
      <geom type="box" size=".05 .25 .5" rgba=".9 .9 0 1" mass="2"/>

      <!-- ARM -->

    <body>
        <inertial pos = "0 0 0" quat="0.5 0.5 -0.5 0.5" mass = "1" diaginertia = "0.0072 0.00443333 0.00443333"/>
        <geom type = "mesh" mesh = "servo_motor" rgba = "0.1 0.1 0.1 1" pos = "-0.05 -0.023 -0.06" euler = "0 0 90"/>

        <body name="arm_servo">
            <inertial pos = "0 0.5 0.4" quat = "0.5 0.5 -0.5 0.5" mass = "1" />
            <geom type = "mesh"  mesh = "servo_motor" rgba = "0.1 0.1 0.1 1" pos = "-0.2 -0.05 -0.07" euler = "0 0 0"/>
            <joint name="elbow_joint" type="hinge" class= "UR5" pos = "-0.1 0 0" axis = "-1 0 0" limited = "true" range = "-180  90 " />

            <body name = "forearm" >
                <geom type = "mesh" mesh = "bracket" rgba="0.1 0.1 0.1 1" pos = "-0.15 -0.054 0.1" euler = "180 -90 -90"/>
                <joint name="shoulder_joint" type="hinge" class= "UR5" pos = "-0.175 -0.02 0.01" axis = "0 1 0" limited = "true" range = "-90 90" />
                <body>
                    <geom type = "mesh" mesh = "bracket" rgba="0.1 0.1 0.1 1" pos = "-0.15 -0.054 0.2" euler = "0 -90 90"/>
                    <body>
                        <geom type = "mesh" mesh = "bracket" rgba="0.1 0.1 0.1 1" pos = "-0.205 -0.054 0.2" euler = "0 90 90"/>
                        <body>
                            <geom type = "mesh"  mesh = "servo_motor" rgba = "0.1 0.1 0.1 1" pos = "-0.16 -0.051 0.365" euler = "0 180 0" />
                            <joint name="arm_joint" type="hinge" class= "UR5" pos = "-0.182 -0.02 0.29" axis = "0 1 0" limited = "true" range = "-90 90" />
                            <body> 
                                <geom size = "0.02 0.004 0.07" pos = "-0.16 0.002 0.4" rgba="0.1 0.1 0.1 1" type ="box" euler="0 0 90" />
                                <body>
                                    <geom type = "mesh"  mesh = "servo_motor" rgba = "0.1 0.1 0.1 1" pos = "-0.2 -0.05  0.41" euler = "0 0 0" />
                                    <body>
                                        <geom type = "mesh" mesh = "bracket" rgba="0.1 0.1 0.1 1" pos = "-0.2 0.05 0.58" euler = "180 90 90"/>
                                        <joint name="wrist_joint" type="hinge" class= "UR5" pos = "-0.18 0.01 0.49" axis = "0 -1 0" limited = "true" range = "-90 90" />
                                        <body >
                                            <inertial pos="0.00021987 -2.3546e-10 0.030163"  quat="0.707058 0.00723369 0.00723345 0.707081" mass="0.30915" diaginertia="0.00030737 0.000289758 0.000199102" />
                                            <geom type="mesh" rgba="0.1 0.1 0.1 1" pos="-0.18 -0.005 0.58" euler="0 0 90" friction="0.8 0.8 0.8" mesh="robotiq_85_base_link_coarse" />
                                            <joint name="cam_joint" type="hinge" class="UR5" pos="-0.18 -0.005 0.58" axis="0 0 1" limited = "true" range = "-180 180"/>
                                            <camera name = "endcam" pos = "-0.18 -0.005 0.68" euler="0 180 0"/>
                                        </body>
                                    </body>
                                </body>
                            </body>
                        </body>
                    </body>
                </body>
            </body>
        </body>
    </body>

    

      <!-- WHEELS -->

      <body pos="0.08 0.2 0.45" euler="0 90 0">
      <!-- <joint name="cyl-axle-l-1" type="hinge" axis="0 0 -1" armature="0.01"/> -->
        <joint name="cyl-axle-l" type="hinge" axis="0 0 -1" limited="true" range="-0.01 0.01" />
        <geom type="cylinder" size="0.01 0.03" rgba="0.5 0.5 0.5 1" mass="0.25" friction="2"/>
        
            <body pos="0.001 0.001 0.035">
                <!-- <joint name="axle-l" type="hinge" axis="0 0 1"/> -->
                <geom type="box" size=".02 0.025 0.025" rgba = "1 1 1 1" mass="0.25"/>  
            </body>
        
            <body pos="0.001 0.02 0.045" euler="90 0 0">
                <geom type="cylinder" size=".01 .03" rgba = "1 1 1 1" />  
            </body>
            <body pos=".003 .05 .045" euler="90 0 0">
                <joint name="wheel-l" type="hinge" axis="0 0 -1"/>
                <geom type="cylinder" size="0.04 0.01" rgba="0.5 0.5 .5 1" friction="1"/>
            </body>
      </body>
      

      <body pos="0.08 -0.2 0.45" euler="0 90 0">
        <!-- <joint name="cyl-axle-r-1" type="hinge" axis="0 0 -1" armature="0.01"/> -->
        <joint name="cyl-axle-r" type="hinge" axis="0 0 -1" limited="true" range="-0.01 0.01"/>
        <geom type="cylinder" size="0.01 0.03" rgba="0.5 0.5 0.5 1" mass="0.25" friction="2"/>
            <body pos="0.001 -0.001 0.035">
                <!-- <joint name="axle-r" type="hinge" axis="0 0 -1"/> -->
                <geom type="box" size=".02 0.025 0.025" rgba = "1 1 1 1" mass="0.25" />  
            </body>
            <body pos="0.001 -0.02 0.045" euler="90 0 0">
                <geom type="cylinder" size=".01 .03" rgba = "1 1 1 1" />  
            </body>
            <body pos=".003 -.05 .045" euler="90 0 0">
                <joint name="wheel-r" type="hinge" axis="0 0 1"/>
                <geom type="cylinder" size="0.04 0.01" rgba="0.5 0.5 .5 1" friction="1"/>
            </body>
      </body>
      
      
      <body pos="0.08 0.2 -0.45" euler="0 90 0">
      <!-- <joint name="cyl-axle-r-l-1" type="hinge" axis="0 0 -1" armature="0.01"/> -->
        <joint name="cyl-axle-r-l" type="hinge" axis="0 0 -1" limited="true" range="-0.01 0.01"/>
        <geom type="cylinder" size="0.01 0.03" rgba="0.5 0.5 0.5 1" mass="0.25" friction="2"/>
            <body pos="0.001 0.001 0.035">
                <!-- <joint name="axle-r-l" type="hinge" axis="0 0 -1"/> -->
                <geom type="box" size=".02 0.025 0.025" rgba = "1 1 1 1" mass="0.25"/>  
            </body>
            <body pos="0.001 0.02 0.045" euler="90 0 0">
                <geom type="cylinder" size=".01 .03" rgba = "1 1 1 1" />  
            </body>
            <body pos=".003 .05 .035" euler="90 0 0">
                <joint name="wheel-r-l" type="hinge" axis="0 0 -1"/>
                <geom type="cylinder" size="0.04 0.01" rgba="0.5 0.5 .5 1" friction="1"/>
            </body>
      </body>
      

      <body pos="0.08 -0.2 -0.45" euler="0 90 0">
      <!-- <joint name="cyl-axle-r-r-1" type="hinge" axis="0 0 -1" armature="0.01"/> -->
        <joint name="cyl-axle-r-r" type="hinge" axis="0 0 -1" limited="true" range="-0.01 0.01"/>
        <geom type="cylinder" size="0.01 0.03" rgba="0.5 0.5 0.5 1" mass="0.25" friction="2"/>
            <body pos="0.001 0.001 0.035">
                <!-- <joint name="axle-r-r" type="hinge" axis="0 0 -1"/> -->
                <geom type="box" size=".02 0.025 0.025" rgba = "1 1 1 1" mass="0.25"/>  
            </body>
            <body pos="0.001 -0.02 0.045" euler="90 0 0">
                <geom type="cylinder" size=".01 .03" rgba = "1 1 1 1" />  
            </body>
            <body pos=".003 -.05 .035" euler="90 0 0">
                <joint name="wheel-r-r" type="hinge" axis="0 0 1"/>
                <geom type="cylinder" size="0.04 0.01" rgba="0.5 0.5 .5 1" friction="1"/>
            </body>
      </body>
      

    </body>
    <!-- Obstaclce objects not fully made -->
    <!-- <body>
        <geom type="cylinder" size=".25 .5" pos="0 -7 0.5" mass=".5"  friction="2" condim="3"/>
        <joint name="joint_1" type="slide" pos="0 -7 0" axis="0 1 0"/>
    </body>
    <body>
        <geom type="cylinder" size=".25 .5" pos="10 0 0.5" mass=".5"  friction="2" condim="3"/>
        <joint name="joint_2" type="slide" pos="10 0 0" axis="1 0 0"/>
    </body>
    <body>
        <geom type="cylinder" size=".25 .5" pos="-2 7 0.5" mass=".5"  friction="2" condim="3"/>
        <joint name="joint_3" type="slide" pos="-2 7 0" axis="0 1 0"/>
    </body>
    <body>
        <geom type="cylinder" size=".25 .5" pos="3 10 0.5" mass=".5"  friction="2" condim="3"/>
        <joint name="joint_4" type="slide" pos="3 10 0" axis="0 1 0"/>
    </body>
    <body>
        <geom type="cylinder" size=".25 .5" pos="4 4 0.5" mass=".5"  friction="2" condim="3"/>
        <joint name="joint_5" type="slide" pos="4 4 0" axis="0 1 0"/>
    </body>
    <body>
        <geom type="cylinder" size=".25 .5" pos="9 6 0.5" mass=".5"  friction="2" condim="3"/>
        <joint name="joint_6" type="slide" pos="9 6 0" axis="0 1 0"/>
    </body>
    <body>
        <geom type="cylinder" size=".25 .5" pos="7 -3 0.5" mass=".5"  friction="2" condim="3"/>
        <joint name="joint_7" type="slide" pos="7 -3 0" axis="0 -1 0"/>
    </body>
    <body>
        <geom type="cylinder" size=".25 .5" pos="2 -1.5 0.5" mass=".5"  friction="2" condim="3"/>
        <joint name="joint_8" type="slide" pos="2 -1.5 0" axis="0 -1 0"/>
    </body>
    <body>
        <geom type="cylinder" size=".25 .5" pos="4.5 -6 0.5" mass=".5"  friction="2" condim="3"/>
        <joint name="joint_9" type="slide" pos="4.5 -6 0" axis="0 -1 0"/>
    </body> -->
    














  </worldbody>
  <!-- Motor to control the arm -->
  <actuator>
    <motor name='base_servo_motor' ctrllimited="true" ctrlrange="-1 1" joint='elbow_joint' gear="80"/>
    <motor name="shoulder_pan_T" ctrllimited="true" ctrlrange="-2 2" joint="shoulder_joint" gear="100"/>
    <motor name="arm_joint_T" ctrllimited="true" ctrlrange="-0.07 0.07" joint="arm_joint" gear="50"/>
    <motor name="wrist_joint_T" ctrllimited="true" ctrlrange="-.5 .5" joint="wrist_joint" gear="10"/>
    <motor name="cam_joint" ctrllimited="true" ctrlrange="-.5 .5" joint="cam_joint" gear="1"/>
  </actuator>
  <!-- Motors to control the movement of wheels -->
  <actuator>
    <motor name="axle-l-r" joint="cyl-axle-l" ctrllimited="true" ctrlrange="-0.2 0.2" gear="1.5"/>
    <motor name="right-l-r" joint="cyl-axle-r" ctrllimited="true" ctrlrange="-0.2 0.2" gear="1.5"/>
    <motor name="cyl-right-l" joint="wheel-l" ctrllimited="true" ctrlrange="-.2 .2" gear="1"/>
    <motor name="cyl-right-r" joint="wheel-r" ctrllimited="true" ctrlrange="-.2 .2" gear="1"/>
    <motor name="cyl-right-r-l" joint="wheel-r-l" ctrllimited="true" ctrlrange="-.2 .2" gear="1"/>
    <motor name="cyl-right-r-r" joint="wheel-r-r" ctrllimited="true" ctrlrange="-.2 .2" gear="1"/>
  </actuator>
  <!-- <actuator>
    <velocity name="joint_1" joint="joint_1" ctrllimited="true" ctrlrange="-.5 .5" kv="10"/>
    <velocity name="joint_2" joint="joint_2" ctrllimited="true" ctrlrange="-.5 .5" kv="10"/>
    <velocity name="joint_3" joint="joint_3" ctrllimited="true" ctrlrange="-.5 .5" kv="10"/>
    <velocity name="joint_4" joint="joint_4" ctrllimited="true" ctrlrange="-.5 .5" kv="10"/>
    <velocity name="joint_5" joint="joint_5" ctrllimited="true" ctrlrange="-.5 .5" kv="10"/>
    <velocity name="joint_6" joint="joint_6" ctrllimited="true" ctrlrange="-.5 .5" kv="10"/>
    <velocity name="joint_7" joint="joint_7" ctrllimited="true" ctrlrange="-.5 .5" kv="10"/>
    <velocity name="joint_8" joint="joint_8" ctrllimited="true" ctrlrange="-.5 .5" kv="10"/>
    <velocity name="joint_9" joint="joint_9" ctrllimited="true" ctrlrange="-.5 .5" kv="10"/>
  </actuator> -->

</mujoco>