<mujoco model="ur5gripper">
    <compiler angle="degree"
            inertiafromgeom="true"
            texturedir="textures/"
            meshdir="mesh/visual/"
            autolimits="true"/>
    <option timestep="2e-3"
            iterations="100"
            tolerance="1e-10"
            impratio="10"/>
    <!-- <size njmax="600" nconmax="150" nstack="300000"/> -->

    <default>
        <site rgba="0.8 0.6 0.7 0.3" type="ellipsoid" group="3"/>
        <!-- <geom contype='1' conaffinity='1' condim='4'  margin="1e-3" solref=".01 1" solimp=".99 .99 .01" /> -->
        <joint armature="0.01" damping=".1"/>
        <default class="UR5">
            <joint damping='.1'/>
        </default>
        <default class="UR5e">
            <joint damping='.1'/>
        </default>
        <default class="GRIPPER">
            <joint damping='.1'/>
        </default>
    </default>

    <visual>
        <map fogstart="3" fogend="5" znear="0.05"/>
        <quality shadowsize="2048"/>
        <scale framelength="0.1"
            framewidth="0.005"
            contactwidth="0.1"
            contactheight="0.005"
            forcewidth="0.01"
            />
    </visual>

    <!--Assets-->
    <asset>
        <!--Meshes-->
        <mesh name="base"           file="base.stl"     />
        <mesh name="shoulder"       file="shoulder.stl" />
        <mesh name="upperarm"       file="upperarm.stl" />
        <mesh name="forearm"        file="forearm.stl"  />
        <mesh name="wrist1"         file="wrist1.stl"   />
        <mesh name="wrist2"         file="wrist2.stl"   />
        <mesh name="wrist3"         file="wrist3.stl"   />
        <mesh name="gripperpalm"    file="palm.STL"     />
        <mesh name="link_0"         file="link_0.STL"   />
        <mesh name="link_1"         file="link_1.STL"   />
        <mesh name="link_2"         file="link_2.STL"   />
        <mesh name="link_3"         file="link_3.STL"   />
        <mesh name="servo_motor"    file="servo_motor.stl"   scale="0.002 0.0025 0.002"  />
        <mesh name="bracket"        file="bracket.STL"       scale="0.002 0.002 0.002"  />

        <mesh name="robotiq_85_base_link_coarse" file="robotiq_85_base_link_coarse.STL" />
        <mesh name="inner_knuckle_coarse" file="inner_knuckle_coarse.STL" />
        <mesh name="inner_finger_coarse" file="inner_finger_coarse.STL" />
        <mesh name="outer_knuckle_coarse" file="outer_knuckle_coarse.STL" />
        <mesh name="outer_finger_coarse" file="outer_finger_coarse.STL" />

        <!--Textures-->
        <texture name="ur5_tex"     type="2d"       builtin="flat" height="32" width="32" rgb1="0.45 0.45 0.45" />
        <texture name="gripper_tex" type="2d"       builtin="flat" height="32" width="32" rgb1="0.45 0.45 0.45" rgb2="0 0 0"/>
        <texture name="bench_tex"   type="2d"       builtin="flat" height="32" width="32" rgb1="0.7 0.7 0.7" />
        <texture name="sky_tex"     type="skybox"   builtin="gradient" width="100" height="100" rgb1="1 1 1" rgb2="0.3 0.3 0.8" />
        <texture name="texgeom"     type="cube"     builtin="flat" mark="cross" width="127" height="1278" rgb1="0.8 0.6 0.4" rgb2="0.8 0.6 0.4" markrgb="1 1 1" random="0.01" />
        <texture name="floor_tex"   type="2d"        builtin="checker" rgb1=".2 .3 .4" rgb2=".1 .2 .3" width="100" height="100" />
        <texture name="wood"        type="cube"     file="wood2.png"/>
        <texture name="metal"        type="cube"     file="metal2.png"/>
        <texture name="plastic"     type="2d"       builtin="flat" height="32" width="32" />


        <!--Materials-->
        <material name="ur5_mat"        texture="ur5_tex"   shininess="0.9" specular="0.75" reflectance="0.3"/>
        <material name="gripper_mat"    texture="gripper_tex"   shininess="0.9" specular="0.75" reflectance="0.4"/>
        <material name='floor_mat'      texture="floor_tex"  shininess="0.8" texrepeat="10 10" specular="0.7"  reflectance="0.5" />
        <material name='geom'           texture="texgeom"   texuniform="true" />
        <material name="bench_mat"      texture="metal"   shininess="0.1" specular="0.5" reflectance="0.2"/>
        <material name="tablecube"      texture="wood" rgba=".8 .8 .8 1"/>
        <material name="hard_plastic"    texture="plastic" />
    </asset>

    <!--Contacts-->
    <!-- <contact>
        <exclude body1="box_link" body2="base_link"/>
        <exclude body1="base_link" body2="shoulder_link"/>
        <exclude body1="shoulder_link" body2="upper_arm_link"/>
        <exclude body1="upper_arm_link" body2="forearm_link"/>
        <exclude body1="forearm_link" body2="wrist_1_link"/>
        <exclude body1="wrist_1_link" body2="wrist_2_link"/>
        <exclude body1="wrist_2_link" body2="wrist_3_link"/>
        <exclude body1="ee_link" body2="wrist_3_link"/>
    </contact> -->


    <!--MODEL DESCRIPTION-->
    <worldbody>
        <!--Lighting parameters-->
        <light name="light3" mode="targetbody" target="box_link" directional="true" pos="1 -1 3" />
        <!-- <light name="light3" mode="targetbody" target="box_link" directional="true" pos="1 1 3" /> -->
        <!--Camera parameters-->
        <!-- <camera name="main1" mode="fixed" target="ee_link" pos="2 2 2.7" axisangle="2 2 -2 1"/>
        <camera name="top_down" mode="fixed" target="ee_link" pos="0 -0.6 2.0" axisangle="2 2 2 0"/>
        <camera name="side" mode="fixed" target="ee_link" pos="0.8 -0.6 1.0" quat="0.5 0.5 0.5 0.5"/> -->
        <!--Floor Property-->
        <geom name='floor' material="floor_mat" pos='0 0 0' size='2.5 2.5 0.1'  type='plane' />

        <!-- PICK BOX GEOMS -->

        <body name="pick_box" pos="0 -0.6 0.0" euler="0 0 90">
            <geom size=".2 .28 .03" pos ="0 0 0.88" type="box" material="bench_mat"/>
            <geom size=".03 .27 .44" pos ="0.23 0.0 0.44" type="box" material="bench_mat"/>
            <geom size=".03 .27 .44" pos ="-0.23 0.0 0.44" type="box" material="bench_mat"/>
            <geom size=".26 .03 .44" pos ="0.0 0.3 0.44" type="box" material="bench_mat"/>
            <geom size=".26 .03 .44" pos ="0.0 -0.3 0.44" type="box" material="bench_mat"/>
            <inertial pos="0 0 0" mass="1000" diaginertia="0 0 0" />
        </body>

<!-- 
        <body name="drop_box" pos="0.6 0.1 0.0">
            <geom size=".2 .3 .03" pos ="0 0 0.615" type="box" material="bench_mat"/>
            <geom size=".03 .3 .4" pos ="0.23 0.0 0.4" type="box" material="bench_mat"/>
            <geom size=".03 .3 .4" pos ="-0.23 0.0 0.4" type="box" material="bench_mat"/>
            <geom size=".26 .03 .4" pos ="0.0 0.33 0.4" type="box" material="bench_mat"/>
            <geom size=".26 .03 .4" pos ="0.0 -0.33 0.4" type="box" material="bench_mat"/>
            <inertial pos="0 0 0" mass="1000" diaginertia="0 0 0" />
        </body> -->


        <!-- ROBO ARM GEOMS -->

        <body name = "box_link" pos = "0 0 0.435">
            <geom size = ".40 0.8 0.03" pos = "0 0 0.4" type = "box" material = "tablecube" />
            <geom size = ".02 .02 .41" pos = "0.35 0.75 -0.025" type = "box" material = "bench_mat" />
            <geom size = ".02 .02 .41" pos = "-0.35 0.75 -0.025" type = "box" material = "bench_mat" />
            <geom size = ".02 .02 .41" pos = "0.35 -0.75 -0.025" type = "box" material = "bench_mat" />
            <geom size = ".02 .02 .41" pos = "-0.35 -0.75 -0.025" type = "box" material = "bench_mat" />
            <geom size = "0.36 0.02 0.02" pos = "0 0.75 -0.3" type = "box" material = "bench_mat"/>
            <geom size = "0.36 0.02 0.02" pos = "0 -0.75 -0.3" type = "box" material = "bench_mat"/>
            <geom size = "0.02 0.76 0.02" pos = "0 0 -0.3" type = "box" material = "bench_mat"/>
        <!-- <body name="box_link" pos="0 0 0.435">
            <geom size=".40 1.19 .03" pos ="0 0 0.4" type="box" material="tablecube"/>
            <geom size=".29 .19 .03" pos ="0 0 -0.2" type="box" material="bench_mat"/>
            <geom size=".04 .04 .435" pos =".26 .16 0" type="box" material="bench_mat"/>
            <geom size=".04 .04 .435" pos ="-.26 .16 0" type="box" material="bench_mat"/>
            <geom size=".04 .04 .435" pos =".26 -.16 0" type="box" material="bench_mat"/>
            <geom size=".04 .04 .435" pos ="-.26 -.16 0" type="box" material="bench_mat"/>
            <inertial pos="0 0 0" mass="1000" diaginertia="0 0 0" /> -->
            

            <body name="base_rotate_servo">
                <inertial pos = "0 0 0" quat="0.5 0.5 -0.5 0.5" mass = "1" diaginertia = "0.0072 0.00443333 0.00443333"/>
                <geom type = "mesh" mesh = "servo_motor" rgba = "0.1 0.1 0.1 1" pos = "0 0.8 0.423" euler = "90 0 0"/>

                <body name="arm_servo">
                    <inertial pos = "0 0.8 0.43" quat = "0.5 0.5 -0.5 0.5" mass = "1" />
                    <geom type = "mesh"  mesh = "servo_motor" rgba = "0.1 0.1 0.1 1" pos = "0.06 0.8 0.54" euler = "-270 0 90" />
                    <joint name="elbow_joint" type="hinge" class= "UR5" pos = "0.02 0.726 0.42" axis = "0 0 1" limited = "true" range = "-90 90" />
                    <body name = "forearm" >
                        <geom type = "mesh" mesh = "bracket" rgba="0.1 0.1 0.1 1" pos = "-0.0425 0.698 0.653" euler = "270 0 0"/>
                        <joint name="shoulder_joint" type="hinge" class= "UR5" pos = "0.06 0.7255 0.5595" axis = "-1 0 0" limited = "true" range = "-90 90" />
                        <body>
                            <geom type = "mesh" mesh = "bracket" rgba="0.1 0.1 0.1 1" pos = "-0.0425 0.752 0.653" euler = "90 0 0"/>
                            <body>
                                <geom type = "mesh" mesh = "bracket" rgba="0.1 0.1 0.1 1" pos = "-0.0425 0.698 0.774" euler = "270 0 0"/>
                                <body>
                                    <geom type = "mesh" mesh = "bracket" rgba="0.1 0.1 0.1 1" pos = "-0.0425 0.752 0.774" euler = "90 0 0"/>
                                    <!-- <body>
                                        <geom type = "mesh"  mesh = "servo_motor" rgba = "0.1 0.1 0.1 1" pos = "-0.035 0.70568 0.9413" euler = "180 0 270" />
                                        <joint name="arm_joint" type="hinge" class= "UR5" pos = "-0.04 0.7248 0.8672" axis = "1 0 0" limited = "true" range = "-90 90" />
                                        <body>
                                            <geom size = "0.02 0.004 0.07" pos = "0.01 0.746 0.98" rgba="0.1 0.1 0.1 1" type ="box" />
                                            <body>
                                                <geom type = "mesh"  mesh = "servo_motor" rgba = "0.1 0.1 0.1 1" pos = "0.055 0.704 0.98" euler = "180 180 270" />
                                                <body>
                                                    <geom type = "mesh" mesh = "bracket" rgba="0.1 0.1 0.1 1" pos = "-0.046 0.696 1.147" euler = "270 0 0"/>
                                                    <joint name="wrist_joint" type="hinge" class= "UR5" pos = "0.04 0.723 1.054" axis = "-1 0 0" limited = "true" range = "-90 90" /> -->

                                                    <!-- GRIPPER MODEL -->
                                                    <!-- <body name="robotiq_85_base_link" pos="0.0068 0.7221 1.15"  euler = "0 0 0">
                                                        <inertial pos="0.00021987 -2.3546e-10 0.030163"  quat="0.707058 0.00723369 0.00723345 0.707081" mass="0.30915" diaginertia="0.00030737 0.000289758 0.000199102" />
                                                        <geom type="mesh" rgba="0.1 0.1 0.1 1" friction="0.8 0.8 0.8" mesh="robotiq_85_base_link_coarse" />
                                                        <body name="left_inner_knuckle" pos="0.0127 0 0.0693075">
                                                            <inertial pos="0.0170975 -3.93809e-10 0.0224918"   quat="0.947655 0 -0.319297 0" mass="0.0110931" diaginertia="5.59353e-06 3.96549e-06 1.88108e-06" />
                                                            <geom type="mesh" rgba="0.6 0.4 0 1" friction="0.8 0.8 0.8" mesh="inner_knuckle_coarse" />
                                                            <joint name="base_to_lik" class="GRIPPER" pos="0 0 0" axis="0 1 0" limited="true" range="-90 90" />
                                                                <body name="left_inner_finger" pos="0.0345853 0 0.045497" >
                                                                    <inertial pos="0.00602756 0 0.00669926"  quat="0.699065 0.106339 0.106339 0.699065" mass="0.00724255" diaginertia="1.70064e-06 1.58577e-06 3.69621e-07" />
                                                                    <geom type="mesh" rgba="0.6 0.4 0 1" friction="0.8 0.8 0.8" mesh="inner_finger_coarse" />
                                                                </body>
                                                        </body>
                                                        <body name="right_inner_knuckle" pos="-0.0127 0 0.0693075" quat="0 0 0 1">
                                                            <inertial pos="0.0168606 3.93808e-10 0.02267"  quat="0.949317 0 -0.314322 0" mass="0.0110931" diaginertia="5.59353e-06 3.96549e-06 1.88108e-06" />
                                                            <geom type="mesh" rgba="0.6 0.4 0 1" friction="0.8 0.8 0.8" mesh="inner_knuckle_coarse" />
                                                            <joint name="base_to_rik" class="GRIPPER" pos="0 0 0" axis="0 1 0" limited="true" range="-90 90" />
                                                            <body name="right_inner_finger" pos="0.034106 0 0.0458574">
                                                                <inertial pos="0.00602756 0 0.00669926"  quat="0.699065 0.106339 0.106339 0.699065" mass="0.00724255" diaginertia="1.70064e-06 1.58577e-06 3.69621e-07" />
                                                                <geom type="mesh" rgba="0.6 0.4 0 1" friction="0.8 0.8 0.8" mesh="inner_finger_coarse" />
                                                            </body>
                                                        </body>
                                                    </body> -->
                                                    <!-- GRIPPER MODEL ENDS -->
                                                <!-- </body>
                                            </body>
                                        </body>
                                    </body> -->
                                </body>
                            </body>
                        </body>
                    </body>
                </body>
            </body>
        </body>
        



        <!-- OBJECTS GEOMS -->
        <body name="box_1" pos=".0 -.6 0.95">
            <joint armature="0" axis="1 0 0" damping="0" limited="true" name="box_1_x" pos="0 0 0" range="-286 286" stiffness="0" type="slide"/>
            <joint armature="0" axis="0 1 0" damping="0" limited="true" name="box_1_y" pos="0 0 0" range="-286 286" stiffness="0" type="slide"/>
            <joint armature="0" axis="0 0 1" damping="0" limited="true" name="box_1_z" pos="0 0 0" range="-2. 2." stiffness="0" type="slide"/>
            <joint armature="0" damping="0" name="box_1_rot" pos="0 0 0" stiffness="0" type="ball"/>
            <geom name="box_1" pos="0 1 0" material="tablecube" size="0.02 0.02 0.02" type="box"/>
        </body>

        <body name="box_2" pos=".0 -.6 1.1">
            <joint armature="0" axis="1 0 0" damping="0" limited="true" name="box_2_x" pos="0 0 0" range="-286 286" stiffness="0" type="slide" />
            <joint armature="0" axis="0 1 0" damping="0" limited="true" name="box_2_y" pos="0 0 0" range="-286 286" stiffness="0" type="slide" />
            <joint armature="0" axis="0 0 1" damping="0" limited="true" name="box_2_z" pos="0 0 0" range="-2. 2." stiffness="0" type="slide" />
            <joint armature="0" damping="0" name="box_2_rot" pos="0 0 0" stiffness="0" type="ball"/>
            <geom name="box_2" pos="0 0 0" rgba="0.0 0.5 0.8 1" size="0.015 0.015 0.015" type="box"/>
        </body>

        <body name="box_3" pos=".0 -.6 1.2">
            <joint armature="0" axis="1 0 0" damping="0" limited="true" name="box_3_x" pos="0 0 0" range="-286 286" stiffness="0" type="slide"/>
            <joint armature="0" axis="0 1 0" damping="0" limited="true" name="box_3_y" pos="0 0 0" range="-286 286" stiffness="0" type="slide"/>
            <joint armature="0" axis="0 0 1" damping="0" limited="true" name="box_3_z" pos="0 0 0" range="-2. 2." stiffness="0" type="slide"/>
            <joint armature="0" damping="0" name="box_3_rot" pos="0 0 0" stiffness="0" type="ball"/>
            <geom name="box_3" pos="0 0 0" rgba="0.8 0.8 0.1 1" size="0.025 0.025 0.025" type="box"/>
        </body>

        <body name="ball_1" pos=".0 -.6 1.3">
            <joint armature="0" axis="1 0 0" damping="0" limited="true" name="ball_1_x" pos="0 0 0" range="-286 286" stiffness="0" type="slide"/>
            <joint armature="0" axis="0 1 0" damping="0" limited="true" name="ball_1_y" pos="0 0 0" range="-286 286" stiffness="0" type="slide"/>
            <joint armature="0" axis="0 0 1" damping="0" limited="true" name="ball_1_z" pos="0 0 0" range="-2. 2." stiffness="0" type="slide"/>
            <joint armature="0" damping="0.001" name="ball_1_rot" pos="0 0 0" stiffness="0" type="ball"/>
            <geom name="ball_1" pos="0 0 0" rgba="0.9 0.2 0.2 1" size=".03" type="sphere"/>
        </body>

        <body name="ball_2" pos=".0 -.6 1.4">
            <joint armature="0" axis="1 0 0" damping="0" limited="true" name="ball_2_x" pos="0 0 0" range="-286 286" stiffness="0" type="slide"/>
            <joint armature="0" axis="0 1 0" damping="0" limited="true" name="ball_2_y" pos="0 0 0" range="-286 286" stiffness="0" type="slide"/>
            <joint armature="0" axis="0 0 1" damping="0" limited="true" name="ball_2_z" pos="0 0 0" range="-2. 2." stiffness="0" type="slide"/>
            <joint armature="0" damping="0.001" name="ball_2_rot" pos="0 0 0" stiffness="0" type="ball"/>
            <geom name="ball_2" pos="0 0 0" material="geom" size=".025" type="sphere"/>
        </body>

        <body name="ball_3" pos=".0 -.6 1.5">
            <joint armature="0" axis="1 0 0" damping="0" limited="true" name="ball_3_x" pos="0 0 0" range="-286 286" stiffness="0" type="slide"/>
            <joint armature="0" axis="0 1 0" damping="0" limited="true" name="ball_3_y" pos="0 0 0" range="-286 286" stiffness="0" type="slide"/>
            <joint armature="0" axis="0 0 1" damping="0" limited="true" name="ball_3_z" pos="0 0 0" range="-2. 2." stiffness="0" type="slide"/>
            <joint armature="0" damping="0.001" name="ball_3_rot" pos="0 0 0" stiffness="0" type="ball"/>
            <geom name="ball_3" pos="0 0 0" rgba="0.2 0.2 0.5 1" size=".02" type="sphere"/>
        </body>


    </worldbody>

    <!-- <equality>
        <joint name="fingers" joint1="base_to_rik" joint2="base_to_lik" polycoef="0 1 0 0 0"/>
    </equality> -->

    <actuator>
        <motor name='base_servo_motor' ctrllimited="true" ctrlrange="-2 2" joint='elbow_joint' gear="101"/>
        <motor name="shoulder_pan_T" ctrllimited="true" ctrlrange="-20 20" joint="shoulder_joint" gear="101"/>
        <position name="pos_base_servo_motor" joint="elbow_joint" ctrlrange="-2 2" kp="100"/>
        <velocity name="vel_base_servo_motor" joint="elbow_joint" kv="10"/>
        <position name="pos_sh_servo_motor" joint="shoulder_joint" ctrlrange="-2 2" kp="100"/>
        <velocity name="vel_sh_servo_motor" joint="shoulder_joint" kv="10"/>
        <!-- <motor name="arm_joint_T" ctrllimited="true" ctrlrange="-0.07 0.07" joint="arm_joint" gear="101"/>
        <motor name="wrist_joint_T" ctrllimited="true" ctrlrange="-45 0" joint="wrist_joint" gear="101"/>
        <motor name='gripper_motor' ctrllimited="true" ctrlrange="-0.01 0.01" joint='base_to_lik' gear="101"/> -->
    </actuator>


</mujoco>
